Workbook

Sheet DM1
B4: 1a. Tabel Kriteria dan Bobot Kriteria | G4: 3. Matriks Keputusan dengan Nilai Numerik | N4: 6. Solusi ideal Posotif dan Negatif
B5: Kriteria | C5: Sub Kriteria | D5: Bobot | H5: A1 | I5: A2 | J5: A3 | K5: A4 | L5: A5 | O5: Solusi Ideal Positif | P5: Solusi Ideal Negatif
B6: Indisipliner (C1) | C6: Absen tanpa Konfirmasi (P1) | D6: 0.03 | E6: cost | G6: P1 | H6: 0 | I6: 2 | J6: 3 | K6: 0 | L6: 1 | N6: P1 | O6: =MIN(H44:L44) -> 0 | P6: =MAX(H44:L44) -> 0.024053512
C7: Jumlah Surat Peringatan [sp] (P2) | D7: 0.04 | E7: cost | G7: P2 | H7: 0 | I7: 1 | J7: 0 | K7: 0 | L7: 1 | N7: P2 | O7: =MIN(H45:L45) -> 0 | P7: =MAX(H45:L45) -> 0.028284271
B8: Pemrograman (C2) | C8: Pemrograman Web (P3) | D8: 0.15 | E8: benefit | G8: P3 | H8: 80 | I8: 60 | J8: 70 | K8: 50 | L8: 60 | N8: P3 | O8: =MAX(H46:L46) -> 0.082807867 | P8: =MIN(H46:L46) -> 0.051754917
C9: Pemrograman Mobile (P4) | D9: 0.13 | E9: benefit | G9: P4 | H9: 70 | I9: 80 | J9: 80 | K9: 80 | L9: 80 | N9: P4 | O9: =MAX(H47:L47) -> 0.059550227 | P9: =MIN(H47:L47) -> 0.052106448
C10: Layanan Web (P5) | D10: 0.11 | E10: benefit | G10: P5 | H10: 100 | I10: 80 | J10: 90 | K10: 50 | L10: 70 | N10: P5 | O10: =MAX(H48:L48) -> 0.061588176 | P10: =MIN(H48:L48) -> 0.030794088
B11: Database (C3) | C11: Query (P6) | D11: 0.09 | E11: benefit | G11: P6 | H11: 70 | I11: 80 | J11: 90 | K11: 90 | L11: 70 | N11: P6 | O11: =MAX(H49:L49) -> 0.045 | P11: =MIN(H49:L49) -> 0.035
C12: Teori Database (P7) | D12: 0.08 | E12: benefit | G12: P7 | H12: 40 | I12: 80 | J12: 80 | K12: 80 | L12: 90 | N12: P7 | O12: =MAX(H50:L50) -> 0.042352941 | P12: =MIN(H50:L50) -> 0.018823529
B13: Desain (C4) | C13: UI (P8) | D13: 0.04 | E13: benefit | G13: P8 | H13: 80 | I13: 70 | J13: 80 | K13: 80 | L13: 80 | N13: P8 | O13: =MAX(H51:L51) -> 0.018323147 | P13: =MIN(H51:L51) -> 0.016032753
C14: UX (P9) | D14: 0.04 | E14: benefit | G14: P9 | H14: 90 | I14: 90 | J14: 80 | K14: 90 | L14: 90 | N14: P9 | O14: =MAX(H52:L52) -> 0.018276231 | P14: =MIN(H52:L52) -> 0.016245539
C15: CSS (P10) | D15: 0.05 | E15: benefit | G15: P10 | H15: 80 | I15: 60 | J15: 70 | K15: 60 | L15: 40 | N15: P10 | O15: =MAX(H53:L53) -> 0.028213825 | P15: =MIN(H53:L53) -> 0.014106912
B16: Jaringan (C5) | C16: Jaringan (P11) | D16: 0.06 | E16: benefit | G16: P11 | H16: 40 | I16: 80 | J16: 80 | K16: 80 | L16: 90 | N16: P11 | O16: =MAX(H54:L54) -> 0.031764706 | P16: =MIN(H54:L54) -> 0.014117647
C17: Keamanan (P12) | D17: 0.06 | E17: benefit | G17: P12 | H17: 70 | I17: 80 | J17: 60 | K17: 60 | L17: 50 | N17: P12 | O17: =MAX(H55:L55) -> 0.033123147 | P17: =MIN(H55:L55) -> 0.020701967
C18: Insinyur Sistem (P13) | D18: 0.07 | E18: benefit | G18: P13 | H18: 80 | I18: 70 | J18: 80 | K18: 80 | L18: 80 | N18: P13 | O18: =MAX(H56:L56) -> 0.032065507 | P18: =MIN(H56:L56) -> 0.028057318
C19: Pengalaman Dukungan IT (P14) | D19: 0.05 | E19: benefit | G19: P14 | H19: 40 | I19: 80 | J19: 60 | K19: 80 | L19: 80 | N19: P14 | O19: =MAX(H57:L57) -> 0.025607376 | P19: =MIN(H57:L57) -> 0.012803688
G23: 3. Matriks Keputusan Ternormalisasi | N23: 7. Jarak Tiap Alternatif dari Solusi Ideal Posotif dan Negatif
H24: A1 | I24: A2 | J24: A3 | K24: A4 | L24: A5
G25: P1 | H25: =H6/POWER(($H6^2+$I6^2+$J6^2+$K6^2+$L6^2), 0.5) -> 0 | I25: =I6/POWER(($H6^2+$I6^2+$J6^2+$K6^2+$L6^2), 0.5) -> 0.53452248 | J25: =J6/POWER(($H6^2+$I6^2+$J6^2+$K6^2+$L6^2), 0.5) -> 0.80178373 | K25: =K6/POWER(($H6^2+$I6^2+$J6^2+$K6^2+$L6^2), 0.5) -> 0 | L25: =L6/POWER(($H6^2+$I6^2+$J6^2+$K6^2+$L6^2), 0.5) -> 0.26726124 | N25: A1 | O25: =POWER(((O6-H25)^2+(O7-H26)^2+(O8-H27)^2+(O9-H28)^2+(O10-H29)^2+(O11-H30)^2+(O12-H31)^2+(O13-H32)^2+(O14-H33)^2+(O15-H34)^2+(O16-H35)^2+(O17-H36)^2+(O18-H37)^2+(O19-H38)^2),0.5) -> 1.3755175 | P25: =POWER(((H25-P6)^2+(H26-P7)^2+(H27-P8)^2+(H28-P9)^2+(H29-P10)^2+(H30-P11)^2+(H31-P12)^2+(H32-P13)^2+(H33-P14)^2+(H34-P15)^2+(H35-P16)^2+(H36-P17)^2+(H37-P18)^2+(H38-P19)^2),0.5) -> 1.4228038
G26: P2 | H26: =H7/POWER(($H7^2+$I7^2+$J7^2+$K7^2+$L7^2), 0.5) -> 0 | I26: =I7/POWER(($H7^2+$I7^2+$J7^2+$K7^2+$L7^2), 0.5) -> 0.70710678 | J26: =J7/POWER(($H7^2+$I7^2+$J7^2+$K7^2+$L7^2), 0.5) -> 0 | K26: =K7/POWER(($H7^2+$I7^2+$J7^2+$K7^2+$L7^2), 0.5) -> 0 | L26: =L7/POWER(($H7^2+$I7^2+$J7^2+$K7^2+$L7^2), 0.5) -> 0.70710678 | N26: A2 | O26: =POWER(((O6-I25)^2+(O7-I26)^2+(O8-I27)^2+(O9-I28)^2+(O10-I29)^2+(O11-I30)^2+(O12-I31)^2+(O13-I32)^2+(O14-I33)^2+(O15-I34)^2+(O16-I35)^2+(O17-I36)^2+(O18-I37)^2+(O19-I38)^2),0.5) -> 1.6957934 | P26: =POWER(((I25-P6)^2+(I26-P7)^2+(I27-P8)^2+(I28-P9)^2+(I29-P10)^2+(I30-P11)^2+(I31-P12)^2+(I32-P13)^2+(I33-P14)^2+(I34-P15)^2+(I35-P16)^2+(I36-P17)^2+(I37-P18)^2+(I38-P19)^2),0.5) -> 1.7180705
G27: P3 | H27: =H8/POWER(($H8^2+$I8^2+$J8^2+$K8^2+$L8^2), 0.5) -> 0.55205245 | I27: =I8/POWER(($H8^2+$I8^2+$J8^2+$K8^2+$L8^2), 0.5) -> 0.41403934 | J27: =J8/POWER(($H8^2+$I8^2+$J8^2+$K8^2+$L8^2), 0.5) -> 0.48304589 | K27: =K8/POWER(($H8^2+$I8^2+$J8^2+$K8^2+$L8^2), 0.5) -> 0.34503278 | L27: =L8/POWER(($H8^2+$I8^2+$J8^2+$K8^2+$L8^2), 0.5) -> 0.41403934 | N27: A3 | O27: =POWER(((O6-J25)^2+(O7-J26)^2+(O8-J27)^2+(O9-J28)^2+(O10-J29)^2+(O11-J30)^2+(O12-J31)^2+(O13-J32)^2+(O14-J33)^2+(O15-J34)^2+(O16-J35)^2+(O17-J36)^2+(O18-J37)^2+(O19-J38)^2),0.5) -> 1.6601624 | P27: =POWER(((J25-P6)^2+(J26-P7)^2+(J27-P8)^2+(J28-P9)^2+(J29-P10)^2+(J30-P11)^2+(J31-P12)^2+(J32-P13)^2+(J33-P14)^2+(J34-P15)^2+(J35-P16)^2+(J36-P17)^2+(J37-P18)^2+(J38-P19)^2),0.5) -> 1.6923286
G28: P4 | H28: =H9/POWER(($H9^2+$I9^2+$J9^2+$K9^2+$L9^2), 0.5) -> 0.40081883 | I28: =I9/POWER(($H9^2+$I9^2+$J9^2+$K9^2+$L9^2), 0.5) -> 0.45807867 | J28: =J9/POWER(($H9^2+$I9^2+$J9^2+$K9^2+$L9^2), 0.5) -> 0.45807867 | K28: =K9/POWER(($H9^2+$I9^2+$J9^2+$K9^2+$L9^2), 0.5) -> 0.45807867 | L28: =L9/POWER(($H9^2+$I9^2+$J9^2+$K9^2+$L9^2), 0.5) -> 0.45807867 | N28: A4 | O28: =POWER(((O6-K25)^2+(O7-K26)^2+(O8-K27)^2+(O9-K28)^2+(O10-K29)^2+(O11-K30)^2+(O12-K31)^2+(O13-K32)^2+(O14-K33)^2+(O15-K34)^2+(O16-K35)^2+(O17-K36)^2+(O18-K37)^2+(O19-K38)^2),0.5) -> 1.4011959 | P28: =POWER(((K25-P6)^2+(K26-P7)^2+(K27-P8)^2+(K28-P9)^2+(K29-P10)^2+(K30-P11)^2+(K31-P12)^2+(K32-P13)^2+(K33-P14)^2+(K34-P15)^2+(K35-P16)^2+(K36-P17)^2+(K37-P18)^2+(K38-P19)^2),0.5) -> 1.4452988
G29: P5 | H29: =H10/POWER(($H10^2+$I10^2+$J10^2+$K10^2+$L10^2), 0.5) -> 0.55989251 | I29: =I10/POWER(($H10^2+$I10^2+$J10^2+$K10^2+$L10^2), 0.5) -> 0.44791401 | J29: =J10/POWER(($H10^2+$I10^2+$J10^2+$K10^2+$L10^2), 0.5) -> 0.50390326 | K29: =K10/POWER(($H10^2+$I10^2+$J10^2+$K10^2+$L10^2), 0.5) -> 0.27994626 | L29: =L10/POWER(($H10^2+$I10^2+$J10^2+$K10^2+$L10^2), 0.5) -> 0.39192476 | N29: A5 | O29: =POWER(((O6-L25)^2+(O7-L26)^2+(O8-L27)^2+(O9-L28)^2+(O10-L29)^2+(O11-L30)^2+(O12-L31)^2+(O13-L32)^2+(O14-L33)^2+(O15-L34)^2+(O16-L35)^2+(O17-L36)^2+(O18-L37)^2+(O19-L38)^2),0.5) -> 1.5868154 | P29: =POWER(((L25-P6)^2+(L26-P7)^2+(L27-P8)^2+(L28-P9)^2+(L29-P10)^2+(L30-P11)^2+(L31-P12)^2+(L32-P13)^2+(L33-P14)^2+(L34-P15)^2+(L35-P16)^2+(L36-P17)^2+(L37-P18)^2+(L38-P19)^2),0.5) -> 1.6120715
G30: P6 | H30: =H11/POWER(($H11^2+$I11^2+$J11^2+$K11^2+$L11^2), 0.5) -> 0.38888889 | I30: =I11/POWER(($H11^2+$I11^2+$J11^2+$K11^2+$L11^2), 0.5) -> 0.44444444 | J30: =J11/POWER(($H11^2+$I11^2+$J11^2+$K11^2+$L11^2), 0.5) -> 0.5 | K30: =K11/POWER(($H11^2+$I11^2+$J11^2+$K11^2+$L11^2), 0.5) -> 0.5 | L30: =L11/POWER(($H11^2+$I11^2+$J11^2+$K11^2+$L11^2), 0.5) -> 0.38888889
G31: P7 | H31: =H12/POWER(($H12^2+$I12^2+$J12^2+$K12^2+$L12^2), 0.5) -> 0.23529412 | I31: =I12/POWER(($H12^2+$I12^2+$J12^2+$K12^2+$L12^2), 0.5) -> 0.47058824 | J31: =J12/POWER(($H12^2+$I12^2+$J12^2+$K12^2+$L12^2), 0.5) -> 0.47058824 | K31: =K12/POWER(($H12^2+$I12^2+$J12^2+$K12^2+$L12^2), 0.5) -> 0.47058824 | L31: =L12/POWER(($H12^2+$I12^2+$J12^2+$K12^2+$L12^2), 0.5) -> 0.52941176
G32: P8 | H32: =H13/POWER(($H13^2+$I13^2+$J13^2+$K13^2+$L13^2), 0.5) -> 0.45807867 | I32: =I13/POWER(($H13^2+$I13^2+$J13^2+$K13^2+$L13^2), 0.5) -> 0.40081883 | J32: =J13/POWER(($H13^2+$I13^2+$J13^2+$K13^2+$L13^2), 0.5) -> 0.45807867 | K32: =K13/POWER(($H13^2+$I13^2+$J13^2+$K13^2+$L13^2), 0.5) -> 0.45807867 | L32: =L13/POWER(($H13^2+$I13^2+$J13^2+$K13^2+$L13^2), 0.5) -> 0.45807867 | N32: 8. Skor Akhir dari Setiap Alternatif
G33: P9 | H33: =H14/POWER(($H14^2+$I14^2+$J14^2+$K14^2+$L14^2), 0.5) -> 0.45690577 | I33: =I14/POWER(($H14^2+$I14^2+$J14^2+$K14^2+$L14^2), 0.5) -> 0.45690577 | J33: =J14/POWER(($H14^2+$I14^2+$J14^2+$K14^2+$L14^2), 0.5) -> 0.40613847 | K33: =K14/POWER(($H14^2+$I14^2+$J14^2+$K14^2+$L14^2), 0.5) -> 0.45690577 | L33: =L14/POWER(($H14^2+$I14^2+$J14^2+$K14^2+$L14^2), 0.5) -> 0.45690577 | O33: A1 | P33: A2 | Q33: A3 | R33: A4 | S33: A5
G34: P10 | H34: =H15/POWER(($H15^2+$I15^2+$J15^2+$K15^2+$L15^2), 0.5) -> 0.56427649 | I34: =I15/POWER(($H15^2+$I15^2+$J15^2+$K15^2+$L15^2), 0.5) -> 0.42320737 | J34: =J15/POWER(($H15^2+$I15^2+$J15^2+$K15^2+$L15^2), 0.5) -> 0.49374193 | K34: =K15/POWER(($H15^2+$I15^2+$J15^2+$K15^2+$L15^2), 0.5) -> 0.42320737 | L34: =L15/POWER(($H15^2+$I15^2+$J15^2+$K15^2+$L15^2), 0.5) -> 0.28213825 | O34: =P25/(O25+P25) -> 0.50844905 | P34: =P26/(O26+P26) -> 0.50326274 | Q34: =P27/(O27+P27) -> 0.50479736 | R34: =P28/(O28+P28) -> 0.50774687 | S34: =P29/(O29+P29) -> 0.50394764
G35: P11 | H35: =H16/POWER(($H16^2+$I16^2+$J16^2+$K16^2+$L16^2), 0.5) -> 0.23529412 | I35: =I16/POWER(($H16^2+$I16^2+$J16^2+$K16^2+$L16^2), 0.5) -> 0.47058824 | J35: =J16/POWER(($H16^2+$I16^2+$J16^2+$K16^2+$L16^2), 0.5) -> 0.47058824 | K35: =K16/POWER(($H16^2+$I16^2+$J16^2+$K16^2+$L16^2), 0.5) -> 0.47058824 | L35: =L16/POWER(($H16^2+$I16^2+$J16^2+$K16^2+$L16^2), 0.5) -> 0.52941176 | N35: Ranking | O35: =RANK(O34,O$34:S$34) -> 1 | P35: =RANK(P34,O$34:S$34) -> 5 | Q35: =RANK(Q34,O$34:S$34) -> 3 | R35: =RANK(R34,O$34:S$34) -> 2 | S35: =RANK(S34,O$34:S$34) -> 4
G36: P12 | H36: =H17/POWER(($H17^2+$I17^2+$J17^2+$K17^2+$L17^2), 0.5) -> 0.48304589 | I36: =I17/POWER(($H17^2+$I17^2+$J17^2+$K17^2+$L17^2), 0.5) -> 0.55205245 | J36: =J17/POWER(($H17^2+$I17^2+$J17^2+$K17^2+$L17^2), 0.5) -> 0.41403934 | K36: =K17/POWER(($H17^2+$I17^2+$J17^2+$K17^2+$L17^2), 0.5) -> 0.41403934 | L36: =L17/POWER(($H17^2+$I17^2+$J17^2+$K17^2+$L17^2), 0.5) -> 0.34503278
G37: P13 | H37: =H18/POWER(($H18^2+$I18^2+$J18^2+$K18^2+$L18^2), 0.5) -> 0.45807867 | I37: =I18/POWER(($H18^2+$I18^2+$J18^2+$K18^2+$L18^2), 0.5) -> 0.40081883 | J37: =J18/POWER(($H18^2+$I18^2+$J18^2+$K18^2+$L18^2), 0.5) -> 0.45807867 | K37: =K18/POWER(($H18^2+$I18^2+$J18^2+$K18^2+$L18^2), 0.5) -> 0.45807867 | L37: =L18/POWER(($H18^2+$I18^2+$J18^2+$K18^2+$L18^2), 0.5) -> 0.45807867
G38: P14 | H38: =H19/POWER(($H19^2+$I19^2+$J19^2+$K19^2+$L19^2), 0.5) -> 0.25607376 | I38: =I19/POWER(($H19^2+$I19^2+$J19^2+$K19^2+$L19^2), 0.5) -> 0.51214752 | J38: =J19/POWER(($H19^2+$I19^2+$J19^2+$K19^2+$L19^2), 0.5) -> 0.38411064 | K38: =K19/POWER(($H19^2+$I19^2+$J19^2+$K19^2+$L19^2), 0.5) -> 0.51214752 | L38: =L19/POWER(($H19^2+$I19^2+$J19^2+$K19^2+$L19^2), 0.5) -> 0.51214752
G42: 3. Matriks Keputusan dengan Nilai Numerik
H43: A1 | I43: A2 | J43: A3 | K43: A4 | L43: A5
G44: P1 | H44: =H25*$D6 -> 0 | I44: =I25*$D6 -> 0.016035675 | J44: =J25*$D6 -> 0.024053512 | K44: =K25*$D6 -> 0 | L44: =L25*$D6 -> 0.0080178373
G45: P2 | H45: =H26*$D7 -> 0 | I45: =I26*$D7 -> 0.028284271 | J45: =J26*$D7 -> 0 | K45: =K26*$D7 -> 0 | L45: =L26*$D7 -> 0.028284271
G46: P3 | H46: =H27*$D8 -> 0.082807867 | I46: =I27*$D8 -> 0.0621059 | J46: =J27*$D8 -> 0.072456884 | K46: =K27*$D8 -> 0.051754917 | L46: =L27*$D8 -> 0.0621059
G47: P4 | H47: =H28*$D9 -> 0.052106448 | I47: =I28*$D9 -> 0.059550227 | J47: =J28*$D9 -> 0.059550227 | K47: =K28*$D9 -> 0.059550227 | L47: =L28*$D9 -> 0.059550227
G48: P5 | H48: =H29*$D10 -> 0.061588176 | I48: =I29*$D10 -> 0.049270541 | J48: =J29*$D10 -> 0.055429359 | K48: =K29*$D10 -> 0.030794088 | L48: =L29*$D10 -> 0.043111723
G49: P6 | H49: =H30*$D11 -> 0.035 | I49: =I30*$D11 -> 0.04 | J49: =J30*$D11 -> 0.045 | K49: =K30*$D11 -> 0.045 | L49: =L30*$D11 -> 0.035
...

Sheet DM2
B4: 1a. Tabel Kriteria dan Bobot Kriteria | G4: 3. Matriks Keputusan dengan Nilai Numerik | N4: 6. Solusi ideal Posotif dan Negatif
B5: Kriteria | C5: Sub Kriteria | D5: Bobot | G5: P | H5: C1 | I5: C2 | J5: C3 | K5: C4 | L5: C5 | O5: Solusi Ideal Positif | P5: Solusi Ideal Negatif
B6: Indisipliner (C1) | C6: Absen tanpa Konfirmasi (P1) | D6: 0.03 | E6: cost | G6: P1 | H6: 1 | I6: 2 | J6: 1 | K6: 0 | L6: 2 | N6: P1 | O6: =MIN(H44:L44) -> 0 | P6: =MAX(H44:L44) -> 0.018973666
C7: Jumlah Surat Peringatan [sp] (P2) | D7: 0.04 | E7: cost | G7: P2 | H7: 0 | I7: 1 | J7: 0 | K7: 0 | L7: 1 | N7: P2 | O7: =MIN(H45:L45) -> 0 | P7: =MAX(H45:L45) -> 0.028284271
B8: Pemrograman (C2) | C8: Pemrograman Web (P3) | D8: 0.15 | E8: benefit | G8: P3 | H8: 70 | I8: 70 | J8: 80 | K8: 60 | L8: 70 | N8: P3 | O8: =MAX(H46:L46) -> 0.076354172 | P8: =MIN(H46:L46) -> 0.057265629
C9: Pemrograman Mobile (P4) | D9: 0.13 | E9: benefit | G9: P4 | H9: 80 | I9: 90 | J9: 80 | K9: 70 | L9: 80 | N9: P4 | O9: =MAX(H47:L47) -> 0.065201551 | P9: =MIN(H47:L47) -> 0.050712317
C10: Layanan Web (P5) | D10: 0.11 | E10: benefit | G10: P5 | H10: 90 | I10: 90 | J10: 100 | K10: 60 | L10: 80 | N10: P5 | O10: =MAX(H48:L48) -> 0.057814716 | P10: =MIN(H48:L48) -> 0.03468883
B11: Database (C3) | C11: Query (P6) | D11: 0.09 | E11: benefit | G11: P6 | H11: 80 | I11: 90 | J11: 80 | K11: 80 | L11: 80 | N11: P6 | O11: =MAX(H49:L49) -> 0.044123512 | P11: =MIN(H49:L49) -> 0.039220899
C12: Teori Database (P7) | D12: 0.08 | E12: benefit | G12: P7 | H12: 50 | I12: 70 | J12: 90 | K12: 70 | L12: 80 | N12: P7 | O12: =MAX(H50:L50) -> 0.043981 | P12: =MIN(H50:L50) -> 0.024433889
B13: Desain (C4) | C13: UI (P8) | D13: 0.04 | E13: benefit | G13: P8 | H13: 70 | I13: 80 | J13: 90 | K13: 80 | L13: 70 | N13: P8 | O13: =MAX(H51:L51) -> 0.020546285 | P13: =MIN(H51:L51) -> 0.015980444
C14: UX (P9) | D14: 0.04 | E14: benefit | G14: P9 | H14: 80 | I14: 100 | J14: 90 | K14: 90 | L14: 80 | N14: P9 | O14: =MAX(H52:L52) -> 0.020254787 | P14: =MIN(H52:L52) -> 0.01620383
C15: CSS (P10) | D15: 0.05 | E15: benefit | G15: P10 | H15: 70 | I15: 90 | J15: 80 | K15: 80 | L15: 70 | N15: P10 | O15: =MAX(H53:L53) -> 0.025682857 | P15: =MIN(H53:L53) -> 0.019975555
B16: Jaringan (C5) | C16: Jaringan (P11) | D16: 0.06 | E16: benefit | G16: P11 | H16: 50 | I16: 70 | J16: 80 | K16: 70 | L16: 50 | N16: P11 | O16: =MAX(H54:L54) -> 0.032966535 | P16: =MIN(H54:L54) -> 0.020604085
C17: Keamanan (P12) | D17: 0.06 | E17: benefit | G17: P12 | H17: 80 | I17: 90 | J17: 80 | K17: 70 | L17: 60 | N17: P12 | O17: =MAX(H55:L55) -> 0.03149344 | P17: =MIN(H55:L55) -> 0.020995626
C18: Insinyur Sistem (P13) | D18: 0.07 | E18: benefit | G18: P13 | H18: 70 | I18: 80 | J18: 80 | K18: 90 | L18: 80 | N18: P13 | O18: =MAX(H56:L56) -> 0.035108527 | P18: =MIN(H56:L56) -> 0.027306632
C19: Pengalaman Dukungan IT (P14) | D19: 0.05 | E19: benefit | G19: P14 | H19: 50 | I19: 90 | J19: 80 | K19: 80 | L19: 70 | N19: P14 | O19: =MAX(H57:L57) -> 0.026749723 | P19: =MIN(H57:L57) -> 0.014860957
G23: 3. Matriks Keputusan Ternormalisasi | N23: 7. Jarak Tiap Alternatif dari Solusi Ideal Posotif dan Negatif
H24: A1 | I24: A2 | J24: A3 | K24: A4 | L24: A5
G25: P1 | H25: =H6/POWER(($H6^2+$I6^2+$J6^2+$K6^2+$L6^2), 0.5) -> 0.31622777 | I25: =I6/POWER(($H6^2+$I6^2+$J6^2+$K6^2+$L6^2), 0.5) -> 0.63245553 | J25: =J6/POWER(($H6^2+$I6^2+$J6^2+$K6^2+$L6^2), 0.5) -> 0.31622777 | K25: =K6/POWER(($H6^2+$I6^2+$J6^2+$K6^2+$L6^2), 0.5) -> 0 | L25: =L6/POWER(($H6^2+$I6^2+$J6^2+$K6^2+$L6^2), 0.5) -> 0.63245553 | N25: A1 | O25: =POWER(((O6-H25)^2+(O7-H26)^2+(O8-H27)^2+(O9-H28)^2+(O10-H29)^2+(O11-H30)^2+(O12-H31)^2+(O13-H32)^2+(O14-H33)^2+(O15-H34)^2+(O16-H35)^2+(O17-H36)^2+(O18-H37)^2+(O19-H38)^2),0.5) -> 1.3005835 | P25: =POWER(((H25-P6)^2+(H26-P7)^2+(H27-P8)^2+(H28-P9)^2+(H29-P10)^2+(H30-P11)^2+(H31-P12)^2+(H32-P13)^2+(H33-P14)^2+(H34-P15)^2+(H35-P16)^2+(H36-P17)^2+(H37-P18)^2+(H38-P19)^2),0.5) -> 1.3344431
G26: P2 | H26: =H7/POWER(($H7^2+$I7^2+$J7^2+$K7^2+$L7^2), 0.5) -> 0 | I26: =I7/POWER(($H7^2+$I7^2+$J7^2+$K7^2+$L7^2), 0.5) -> 0.70710678 | J26: =J7/POWER(($H7^2+$I7^2+$J7^2+$K7^2+$L7^2), 0.5) -> 0 | K26: =K7/POWER(($H7^2+$I7^2+$J7^2+$K7^2+$L7^2), 0.5) -> 0 | L26: =L7/POWER(($H7^2+$I7^2+$J7^2+$K7^2+$L7^2), 0.5) -> 0.70710678 | N26: A2 | O26: =POWER(((O6-I25)^2+(O7-I26)^2+(O8-I27)^2+(O9-I28)^2+(O10-I29)^2+(O11-I30)^2+(O12-I31)^2+(O13-I32)^2+(O14-I33)^2+(O15-I34)^2+(O16-I35)^2+(O17-I36)^2+(O18-I37)^2+(O19-I38)^2),0.5) -> 1.8112733 | P26: =POWER(((I25-P6)^2+(I26-P7)^2+(I27-P8)^2+(I28-P9)^2+(I29-P10)^2+(I30-P11)^2+(I31-P12)^2+(I32-P13)^2+(I33-P14)^2+(I34-P15)^2+(I35-P16)^2+(I36-P17)^2+(I37-P18)^2+(I38-P19)^2),0.5) -> 1.8271961
G27: P3 | H27: =H8/POWER(($H8^2+$I8^2+$J8^2+$K8^2+$L8^2), 0.5) -> 0.44539933 | I27: =I8/POWER(($H8^2+$I8^2+$J8^2+$K8^2+$L8^2), 0.5) -> 0.44539933 | J27: =J8/POWER(($H8^2+$I8^2+$J8^2+$K8^2+$L8^2), 0.5) -> 0.50902781 | K27: =K8/POWER(($H8^2+$I8^2+$J8^2+$K8^2+$L8^2), 0.5) -> 0.38177086 | L27: =L8/POWER(($H8^2+$I8^2+$J8^2+$K8^2+$L8^2), 0.5) -> 0.44539933 | N27: A3 | O27: =POWER(((O6-J25)^2+(O7-J26)^2+(O8-J27)^2+(O9-J28)^2+(O10-J29)^2+(O11-J30)^2+(O12-J31)^2+(O13-J32)^2+(O14-J33)^2+(O15-J34)^2+(O16-J35)^2+(O17-J36)^2+(O18-J37)^2+(O19-J38)^2),0.5) -> 1.5826335 | P27: =POWER(((J25-P6)^2+(J26-P7)^2+(J27-P8)^2+(J28-P9)^2+(J29-P10)^2+(J30-P11)^2+(J31-P12)^2+(J32-P13)^2+(J33-P14)^2+(J34-P15)^2+(J35-P16)^2+(J36-P17)^2+(J37-P18)^2+(J38-P19)^2),0.5) -> 1.6188484
G28: P4 | H28: =H9/POWER(($H9^2+$I9^2+$J9^2+$K9^2+$L9^2), 0.5) -> 0.44582257 | I28: =I9/POWER(($H9^2+$I9^2+$J9^2+$K9^2+$L9^2), 0.5) -> 0.50155039 | J28: =J9/POWER(($H9^2+$I9^2+$J9^2+$K9^2+$L9^2), 0.5) -> 0.44582257 | K28: =K9/POWER(($H9^2+$I9^2+$J9^2+$K9^2+$L9^2), 0.5) -> 0.39009475 | L28: =L9/POWER(($H9^2+$I9^2+$J9^2+$K9^2+$L9^2), 0.5) -> 0.44582257 | N28: A4 | O28: =POWER(((O6-K25)^2+(O7-K26)^2+(O8-K27)^2+(O9-K28)^2+(O10-K29)^2+(O11-K30)^2+(O12-K31)^2+(O13-K32)^2+(O14-K33)^2+(O15-K34)^2+(O16-K35)^2+(O17-K36)^2+(O18-K37)^2+(O19-K38)^2),0.5) -> 1.3757257 | P28: =POWER(((K25-P6)^2+(K26-P7)^2+(K27-P8)^2+(K28-P9)^2+(K29-P10)^2+(K30-P11)^2+(K31-P12)^2+(K32-P13)^2+(K33-P14)^2+(K34-P15)^2+(K35-P16)^2+(K36-P17)^2+(K37-P18)^2+(K38-P19)^2),0.5) -> 1.4131579
G29: P5 | H29: =H10/POWER(($H10^2+$I10^2+$J10^2+$K10^2+$L10^2), 0.5) -> 0.4730295 | I29: =I10/POWER(($H10^2+$I10^2+$J10^2+$K10^2+$L10^2), 0.5) -> 0.4730295 | J29: =J10/POWER(($H10^2+$I10^2+$J10^2+$K10^2+$L10^2), 0.5) -> 0.52558833 | K29: =K10/POWER(($H10^2+$I10^2+$J10^2+$K10^2+$L10^2), 0.5) -> 0.315353 | L29: =L10/POWER(($H10^2+$I10^2+$J10^2+$K10^2+$L10^2), 0.5) -> 0.42047066 | N29: A5 | O29: =POWER(((O6-L25)^2+(O7-L26)^2+(O8-L27)^2+(O9-L28)^2+(O10-L29)^2+(O11-L30)^2+(O12-L31)^2+(O13-L32)^2+(O14-L33)^2+(O15-L34)^2+(O16-L35)^2+(O17-L36)^2+(O18-L37)^2+(O19-L38)^2),0.5) -> 1.6165585 | P29: =POWER(((L25-P6)^2+(L26-P7)^2+(L27-P8)^2+(L28-P9)^2+(L29-P10)^2+(L30-P11)^2+(L31-P12)^2+(L32-P13)^2+(L33-P14)^2+(L34-P15)^2+(L35-P16)^2+(L36-P17)^2+(L37-P18)^2+(L38-P19)^2),0.5) -> 1.6298659
G30: P6 | H30: =H11/POWER(($H11^2+$I11^2+$J11^2+$K11^2+$L11^2), 0.5) -> 0.43578777 | I30: =I11/POWER(($H11^2+$I11^2+$J11^2+$K11^2+$L11^2), 0.5) -> 0.49026124 | J30: =J11/POWER(($H11^2+$I11^2+$J11^2+$K11^2+$L11^2), 0.5) -> 0.43578777 | K30: =K11/POWER(($H11^2+$I11^2+$J11^2+$K11^2+$L11^2), 0.5) -> 0.43578777 | L30: =L11/POWER(($H11^2+$I11^2+$J11^2+$K11^2+$L11^2), 0.5) -> 0.43578777
G31: P7 | H31: =H12/POWER(($H12^2+$I12^2+$J12^2+$K12^2+$L12^2), 0.5) -> 0.30542361 | I31: =I12/POWER(($H12^2+$I12^2+$J12^2+$K12^2+$L12^2), 0.5) -> 0.42759306 | J31: =J12/POWER(($H12^2+$I12^2+$J12^2+$K12^2+$L12^2), 0.5) -> 0.5497625 | K31: =K12/POWER(($H12^2+$I12^2+$J12^2+$K12^2+$L12^2), 0.5) -> 0.42759306 | L31: =L12/POWER(($H12^2+$I12^2+$J12^2+$K12^2+$L12^2), 0.5) -> 0.48867778
G32: P8 | H32: =H13/POWER(($H13^2+$I13^2+$J13^2+$K13^2+$L13^2), 0.5) -> 0.3995111 | I32: =I13/POWER(($H13^2+$I13^2+$J13^2+$K13^2+$L13^2), 0.5) -> 0.45658412 | J32: =J13/POWER(($H13^2+$I13^2+$J13^2+$K13^2+$L13^2), 0.5) -> 0.51365713 | K32: =K13/POWER(($H13^2+$I13^2+$J13^2+$K13^2+$L13^2), 0.5) -> 0.45658412 | L32: =L13/POWER(($H13^2+$I13^2+$J13^2+$K13^2+$L13^2), 0.5) -> 0.3995111 | N32: 8. Skor Akhir dari Setiap Alternatif
G33: P9 | H33: =H14/POWER(($H14^2+$I14^2+$J14^2+$K14^2+$L14^2), 0.5) -> 0.40509575 | I33: =I14/POWER(($H14^2+$I14^2+$J14^2+$K14^2+$L14^2), 0.5) -> 0.50636968 | J33: =J14/POWER(($H14^2+$I14^2+$J14^2+$K14^2+$L14^2), 0.5) -> 0.45573272 | K33: =K14/POWER(($H14^2+$I14^2+$J14^2+$K14^2+$L14^2), 0.5) -> 0.45573272 | L33: =L14/POWER(($H14^2+$I14^2+$J14^2+$K14^2+$L14^2), 0.5) -> 0.40509575 | O33: A1 | P33: A2 | Q33: A3 | R33: A4 | S33: A5
G34: P10 | H34: =H15/POWER(($H15^2+$I15^2+$J15^2+$K15^2+$L15^2), 0.5) -> 0.3995111 | I34: =I15/POWER(($H15^2+$I15^2+$J15^2+$K15^2+$L15^2), 0.5) -> 0.51365713 | J34: =J15/POWER(($H15^2+$I15^2+$J15^2+$K15^2+$L15^2), 0.5) -> 0.45658412 | K34: =K15/POWER(($H15^2+$I15^2+$J15^2+$K15^2+$L15^2), 0.5) -> 0.45658412 | L34: =L15/POWER(($H15^2+$I15^2+$J15^2+$K15^2+$L15^2), 0.5) -> 0.3995111 | O34: =P25/(O25+P25) -> 0.5064249 | P34: =P26/(O26+P26) -> 0.50218812 | Q34: =P27/(O27+P27) -> 0.50565597 | R34: =P28/(O28+P28) -> 0.50671097 | S34: =P29/(O29+P29) -> 0.50204955
G35: P11 | H35: =H16/POWER(($H16^2+$I16^2+$J16^2+$K16^2+$L16^2), 0.5) -> 0.34340141 | I35: =I16/POWER(($H16^2+$I16^2+$J16^2+$K16^2+$L16^2), 0.5) -> 0.48076197 | J35: =J16/POWER(($H16^2+$I16^2+$J16^2+$K16^2+$L16^2), 0.5) -> 0.54944226 | K35: =K16/POWER(($H16^2+$I16^2+$J16^2+$K16^2+$L16^2), 0.5) -> 0.48076197 | L35: =L16/POWER(($H16^2+$I16^2+$J16^2+$K16^2+$L16^2), 0.5) -> 0.34340141 | N35: Ranking | O35: =RANK(O34,O$34:S$34) -> 2 | P35: =RANK(P34,O$34:S$34) -> 4 | Q35: =RANK(Q34,O$34:S$34) -> 3 | R35: =RANK(R34,O$34:S$34) -> 1 | S35: =RANK(S34,O$34:S$34) -> 5
G36: P12 | H36: =H17/POWER(($H17^2+$I17^2+$J17^2+$K17^2+$L17^2), 0.5) -> 0.46656947 | I36: =I17/POWER(($H17^2+$I17^2+$J17^2+$K17^2+$L17^2), 0.5) -> 0.52489066 | J36: =J17/POWER(($H17^2+$I17^2+$J17^2+$K17^2+$L17^2), 0.5) -> 0.46656947 | K36: =K17/POWER(($H17^2+$I17^2+$J17^2+$K17^2+$L17^2), 0.5) -> 0.40824829 | L36: =L17/POWER(($H17^2+$I17^2+$J17^2+$K17^2+$L17^2), 0.5) -> 0.34992711
G37: P13 | H37: =H18/POWER(($H18^2+$I18^2+$J18^2+$K18^2+$L18^2), 0.5) -> 0.39009475 | I37: =I18/POWER(($H18^2+$I18^2+$J18^2+$K18^2+$L18^2), 0.5) -> 0.44582257 | J37: =J18/POWER(($H18^2+$I18^2+$J18^2+$K18^2+$L18^2), 0.5) -> 0.44582257 | K37: =K18/POWER(($H18^2+$I18^2+$J18^2+$K18^2+$L18^2), 0.5) -> 0.50155039 | L37: =L18/POWER(($H18^2+$I18^2+$J18^2+$K18^2+$L18^2), 0.5) -> 0.44582257
G38: P14 | H38: =H19/POWER(($H19^2+$I19^2+$J19^2+$K19^2+$L19^2), 0.5) -> 0.29721915 | I38: =I19/POWER(($H19^2+$I19^2+$J19^2+$K19^2+$L19^2), 0.5) -> 0.53499447 | J38: =J19/POWER(($H19^2+$I19^2+$J19^2+$K19^2+$L19^2), 0.5) -> 0.47555064 | K38: =K19/POWER(($H19^2+$I19^2+$J19^2+$K19^2+$L19^2), 0.5) -> 0.47555064 | L38: =L19/POWER(($H19^2+$I19^2+$J19^2+$K19^2+$L19^2), 0.5) -> 0.41610681
G42: 3. Matriks Keputusan dengan Nilai Numerik
H43: A1 | I43: A2 | J43: A3 | K43: A4 | L43: A5
G44: P1 | H44: =H25*$D6 -> 0.009486833 | I44: =I25*$D6 -> 0.018973666 | J44: =J25*$D6 -> 0.009486833 | K44: =K25*$D6 -> 0 | L44: =L25*$D6 -> 0.018973666
G45: P2 | H45: =H26*$D7 -> 0 | I45: =I26*$D7 -> 0.028284271 | J45: =J26*$D7 -> 0 | K45: =K26*$D7 -> 0 | L45: =L26*$D7 -> 0.028284271
G46: P3 | H46: =H27*$D8 -> 0.0668099 | I46: =I27*$D8 -> 0.0668099 | J46: =J27*$D8 -> 0.076354172 | K46: =K27*$D8 -> 0.057265629 | L46: =L27*$D8 -> 0.0668099
G47: P4 | H47: =H28*$D9 -> 0.057956934 | I47: =I28*$D9 -> 0.065201551 | J47: =J28*$D9 -> 0.057956934 | K47: =K28*$D9 -> 0.050712317 | L47: =L28*$D9 -> 0.057956934
G48: P5 | H48: =H29*$D10 -> 0.052033245 | I48: =I29*$D10 -> 0.052033245 | J48: =J29*$D10 -> 0.057814716 | K48: =K29*$D10 -> 0.03468883 | L48: =L29*$D10 -> 0.046251773
G49: P6 | H49: =H30*$D11 -> 0.039220899 | I49: =I30*$D11 -> 0.044123512 | J49: =J30*$D11 -> 0.039220899 | K49: =K30*$D11 -> 0.039220899 | L49: =L30*$D11 -> 0.039220899
...

Sheet DM3
B4: 1a. Tabel Kriteria dan Bobot Kriteria | G4: 3. Matriks Keputusan dengan Nilai Numerik | N4: 6. Solusi ideal Posotif dan Negatif
B5: Kriteria | C5: Sub Kriteria | D5: Bobot | H5: A1 | I5: A2 | J5: A3 | K5: A4 | L5: A5 | O5: Solusi Ideal Positif | P5: Solusi Ideal Negatif
B6: Indisipliner (C1) | C6: Absen tanpa Konfirmasi (P1) | D6: 0.03 | E6: cost | G6: P1 | H6: 0 | I6: 3 | J6: 2 | K6: 0 | L6: 1 | N6: P1 | O6: =MIN(H44:L44) -> 0 | P6: =MAX(H44:L44) -> 0.024053512
C7: Jumlah Surat Peringatan [sp] (P2) | D7: 0.04 | E7: cost | G7: P2 | H7: 1 | I7: 0 | J7: 1 | K7: 1 | L7: 0 | N7: P2 | O7: =MIN(H45:L45) -> 0 | P7: =MAX(H45:L45) -> 0.023094011
B8: Pemrograman (C2) | C8: Pemrograman Web (P3) | D8: 0.15 | E8: benefit | G8: P3 | H8: 70 | I8: 70 | J8: 70 | K8: 90 | L8: 80 | N8: P3 | O8: =MAX(H46:L46) -> 0.079002774 | P8: =MIN(H46:L46) -> 0.061446602
C9: Pemrograman Mobile (P4) | D9: 0.13 | E9: benefit | G9: P4 | H9: 70 | I9: 100 | J9: 90 | K9: 60 | L9: 80 | N9: P4 | O9: =MAX(H47:L47) -> 0.071562645 | P9: =MIN(H47:L47) -> 0.042937587
C10: Layanan Web (P5) | D10: 0.11 | E10: benefit | G10: P5 | H10: 100 | I10: 100 | J10: 60 | K10: 80 | L10: 90 | N10: P5 | O10: =MAX(H48:L48) -> 0.056354707 | P10: =MIN(H48:L48) -> 0.033812824
B11: Database (C3) | C11: Query (P6) | D11: 0.09 | E11: benefit | G11: P6 | H11: 50 | I11: 80 | J11: 60 | K11: 100 | L11: 90 | N11: P6 | O11: =MAX(H49:L49) -> 0.051449576 | P11: =MIN(H49:L49) -> 0.025724788
C12: Teori Database (P7) | D12: 0.08 | E12: benefit | G12: P7 | H12: 80 | I12: 50 | J12: 50 | K12: 70 | L12: 70 | N12: P7 | O12: =MAX(H50:L50) -> 0.04395538 | P12: =MIN(H50:L50) -> 0.027472113
B13: Desain (C4) | C13: UI (P8) | D13: 0.04 | E13: benefit | G13: P8 | H13: 60 | I13: 80 | J13: 80 | K13: 100 | L13: 100 | N13: P8 | O13: =MAX(H51:L51) -> 0.020965697 | P13: =MIN(H51:L51) -> 0.012579418
C14: UX (P9) | D14: 0.04 | E14: benefit | G14: P9 | H14: 100 | I14: 70 | J14: 80 | K14: 80 | L14: 50 | N14: P9 | O14: =MAX(H52:L52) -> 0.023017414 | P14: =MIN(H52:L52) -> 0.011508707
C15: CSS (P10) | D15: 0.05 | E15: benefit | G15: P10 | H15: 70 | I15: 90 | J15: 70 | K15: 90 | L15: 50 | N15: P10 | O15: =MAX(H53:L53) -> 0.026655699 | P15: =MIN(H53:L53) -> 0.014808722
B16: Jaringan (C5) | C16: Jaringan (P11) | D16: 0.06 | E16: benefit | G16: P11 | H16: 60 | I16: 80 | J16: 50 | K16: 80 | L16: 100 | N16: P11 | O16: =MAX(H54:L54) -> 0.035294118 | P16: =MIN(H54:L54) -> 0.017647059
C17: Keamanan (P12) | D17: 0.06 | E17: benefit | G17: P12 | H17: 60 | I17: 60 | J17: 50 | K17: 60 | L17: 90 | N17: P12 | O17: =MAX(H55:L55) -> 0.03691364 | P17: =MIN(H55:L55) -> 0.020507578
C18: Insinyur Sistem (P13) | D18: 0.07 | E18: benefit | G18: P13 | H18: 60 | I18: 80 | J18: 80 | K18: 80 | L18: 80 | N18: P13 | O18: =MAX(H56:L56) -> 0.032771521 | P18: =MIN(H56:L56) -> 0.024578641
C19: Pengalaman Dukungan IT (P14) | D19: 0.05 | E19: benefit | G19: P14 | H19: 90 | I19: 70 | J19: 100 | K19: 50 | L19: 80 | N19: P14 | O19: =MAX(H57:L57) -> 0.027994626 | P19: =MIN(H57:L57) -> 0.013997313
G23: 3. Matriks Keputusan Ternormalisasi | N23: 7. Jarak Tiap Alternatif dari Solusi Ideal Posotif dan Negatif
H24: A1 | I24: A2 | J24: A3 | K24: A4 | L24: A5
G25: P1 | H25: =H6/POWER(($H6^2+$I6^2+$J6^2+$K6^2+$L6^2), 0.5) -> 0 | I25: =I6/POWER(($H6^2+$I6^2+$J6^2+$K6^2+$L6^2), 0.5) -> 0.80178373 | J25: =J6/POWER(($H6^2+$I6^2+$J6^2+$K6^2+$L6^2), 0.5) -> 0.53452248 | K25: =K6/POWER(($H6^2+$I6^2+$J6^2+$K6^2+$L6^2), 0.5) -> 0 | L25: =L6/POWER(($H6^2+$I6^2+$J6^2+$K6^2+$L6^2), 0.5) -> 0.26726124 | N25: A1 | O25: =POWER(((O6-H25)^2+(O7-H26)^2+(O8-H27)^2+(O9-H28)^2+(O10-H29)^2+(O11-H30)^2+(O12-H31)^2+(O13-H32)^2+(O14-H33)^2+(O15-H34)^2+(O16-H35)^2+(O17-H36)^2+(O18-H37)^2+(O19-H38)^2),0.5) -> 1.4728751 | P25: =POWER(((H25-P6)^2+(H26-P7)^2+(H27-P8)^2+(H28-P9)^2+(H29-P10)^2+(H30-P11)^2+(H31-P12)^2+(H32-P13)^2+(H33-P14)^2+(H34-P15)^2+(H35-P16)^2+(H36-P17)^2+(H37-P18)^2+(H38-P19)^2),0.5) -> 1.515006
G26: P2 | H26: =H7/POWER(($H7^2+$I7^2+$J7^2+$K7^2+$L7^2), 0.5) -> 0.57735027 | I26: =I7/POWER(($H7^2+$I7^2+$J7^2+$K7^2+$L7^2), 0.5) -> 0 | J26: =J7/POWER(($H7^2+$I7^2+$J7^2+$K7^2+$L7^2), 0.5) -> 0.57735027 | K26: =K7/POWER(($H7^2+$I7^2+$J7^2+$K7^2+$L7^2), 0.5) -> 0.57735027 | L26: =L7/POWER(($H7^2+$I7^2+$J7^2+$K7^2+$L7^2), 0.5) -> 0 | N26: A2 | O26: =POWER(((O6-I25)^2+(O7-I26)^2+(O8-I27)^2+(O9-I28)^2+(O10-I29)^2+(O11-I30)^2+(O12-I31)^2+(O13-I32)^2+(O14-I33)^2+(O15-I34)^2+(O16-I35)^2+(O17-I36)^2+(O18-I37)^2+(O19-I38)^2),0.5) -> 1.6291319 | P26: =POWER(((I25-P6)^2+(I26-P7)^2+(I27-P8)^2+(I28-P9)^2+(I29-P10)^2+(I30-P11)^2+(I31-P12)^2+(I32-P13)^2+(I33-P14)^2+(I34-P15)^2+(I35-P16)^2+(I36-P17)^2+(I37-P18)^2+(I38-P19)^2),0.5) -> 1.6682508
G27: P3 | H27: =H8/POWER(($H8^2+$I8^2+$J8^2+$K8^2+$L8^2), 0.5) -> 0.40964402 | I27: =I8/POWER(($H8^2+$I8^2+$J8^2+$K8^2+$L8^2), 0.5) -> 0.40964402 | J27: =J8/POWER(($H8^2+$I8^2+$J8^2+$K8^2+$L8^2), 0.5) -> 0.40964402 | K27: =K8/POWER(($H8^2+$I8^2+$J8^2+$K8^2+$L8^2), 0.5) -> 0.52668516 | L27: =L8/POWER(($H8^2+$I8^2+$J8^2+$K8^2+$L8^2), 0.5) -> 0.46816459 | N27: A3 | O27: =POWER(((O6-J25)^2+(O7-J26)^2+(O8-J27)^2+(O9-J28)^2+(O10-J29)^2+(O11-J30)^2+(O12-J31)^2+(O13-J32)^2+(O14-J33)^2+(O15-J34)^2+(O16-J35)^2+(O17-J36)^2+(O18-J37)^2+(O19-J38)^2),0.5) -> 1.5095107 | P27: =POWER(((J25-P6)^2+(J26-P7)^2+(J27-P8)^2+(J28-P9)^2+(J29-P10)^2+(J30-P11)^2+(J31-P12)^2+(J32-P13)^2+(J33-P14)^2+(J34-P15)^2+(J35-P16)^2+(J36-P17)^2+(J37-P18)^2+(J38-P19)^2),0.5) -> 1.5395709
G28: P4 | H28: =H9/POWER(($H9^2+$I9^2+$J9^2+$K9^2+$L9^2), 0.5) -> 0.38533732 | I28: =I9/POWER(($H9^2+$I9^2+$J9^2+$K9^2+$L9^2), 0.5) -> 0.55048188 | J28: =J9/POWER(($H9^2+$I9^2+$J9^2+$K9^2+$L9^2), 0.5) -> 0.49543369 | K28: =K9/POWER(($H9^2+$I9^2+$J9^2+$K9^2+$L9^2), 0.5) -> 0.33028913 | L28: =L9/POWER(($H9^2+$I9^2+$J9^2+$K9^2+$L9^2), 0.5) -> 0.44038551 | N28: A4 | O28: =POWER(((O6-K25)^2+(O7-K26)^2+(O8-K27)^2+(O9-K28)^2+(O10-K29)^2+(O11-K30)^2+(O12-K31)^2+(O13-K32)^2+(O14-K33)^2+(O15-K34)^2+(O16-K35)^2+(O17-K36)^2+(O18-K37)^2+(O19-K38)^2),0.5) -> 1.5715766 | P28: =POWER(((K25-P6)^2+(K26-P7)^2+(K27-P8)^2+(K28-P9)^2+(K29-P10)^2+(K30-P11)^2+(K31-P12)^2+(K32-P13)^2+(K33-P14)^2+(K34-P15)^2+(K35-P16)^2+(K36-P17)^2+(K37-P18)^2+(K38-P19)^2),0.5) -> 1.6149275
G29: P5 | H29: =H10/POWER(($H10^2+$I10^2+$J10^2+$K10^2+$L10^2), 0.5) -> 0.51231552 | I29: =I10/POWER(($H10^2+$I10^2+$J10^2+$K10^2+$L10^2), 0.5) -> 0.51231552 | J29: =J10/POWER(($H10^2+$I10^2+$J10^2+$K10^2+$L10^2), 0.5) -> 0.30738931 | K29: =K10/POWER(($H10^2+$I10^2+$J10^2+$K10^2+$L10^2), 0.5) -> 0.40985242 | L29: =L10/POWER(($H10^2+$I10^2+$J10^2+$K10^2+$L10^2), 0.5) -> 0.46108397 | N29: A5 | O29: =POWER(((O6-L25)^2+(O7-L26)^2+(O8-L27)^2+(O9-L28)^2+(O10-L29)^2+(O11-L30)^2+(O12-L31)^2+(O13-L32)^2+(O14-L33)^2+(O15-L34)^2+(O16-L35)^2+(O17-L36)^2+(O18-L37)^2+(O19-L38)^2),0.5) -> 1.5264032 | P29: =POWER(((L25-P6)^2+(L26-P7)^2+(L27-P8)^2+(L28-P9)^2+(L29-P10)^2+(L30-P11)^2+(L31-P12)^2+(L32-P13)^2+(L33-P14)^2+(L34-P15)^2+(L35-P16)^2+(L36-P17)^2+(L37-P18)^2+(L38-P19)^2),0.5) -> 1.578438
G30: P6 | H30: =H11/POWER(($H11^2+$I11^2+$J11^2+$K11^2+$L11^2), 0.5) -> 0.28583098 | I30: =I11/POWER(($H11^2+$I11^2+$J11^2+$K11^2+$L11^2), 0.5) -> 0.45732956 | J30: =J11/POWER(($H11^2+$I11^2+$J11^2+$K11^2+$L11^2), 0.5) -> 0.34299717 | K30: =K11/POWER(($H11^2+$I11^2+$J11^2+$K11^2+$L11^2), 0.5) -> 0.57166195 | L30: =L11/POWER(($H11^2+$I11^2+$J11^2+$K11^2+$L11^2), 0.5) -> 0.51449576
G31: P7 | H31: =H12/POWER(($H12^2+$I12^2+$J12^2+$K12^2+$L12^2), 0.5) -> 0.54944226 | I31: =I12/POWER(($H12^2+$I12^2+$J12^2+$K12^2+$L12^2), 0.5) -> 0.34340141 | J31: =J12/POWER(($H12^2+$I12^2+$J12^2+$K12^2+$L12^2), 0.5) -> 0.34340141 | K31: =K12/POWER(($H12^2+$I12^2+$J12^2+$K12^2+$L12^2), 0.5) -> 0.48076197 | L31: =L12/POWER(($H12^2+$I12^2+$J12^2+$K12^2+$L12^2), 0.5) -> 0.48076197
G32: P8 | H32: =H13/POWER(($H13^2+$I13^2+$J13^2+$K13^2+$L13^2), 0.5) -> 0.31448545 | I32: =I13/POWER(($H13^2+$I13^2+$J13^2+$K13^2+$L13^2), 0.5) -> 0.41931393 | J32: =J13/POWER(($H13^2+$I13^2+$J13^2+$K13^2+$L13^2), 0.5) -> 0.41931393 | K32: =K13/POWER(($H13^2+$I13^2+$J13^2+$K13^2+$L13^2), 0.5) -> 0.52414242 | L32: =L13/POWER(($H13^2+$I13^2+$J13^2+$K13^2+$L13^2), 0.5) -> 0.52414242 | N32: 8. Skor Akhir dari Setiap Alternatif
G33: P9 | H33: =H14/POWER(($H14^2+$I14^2+$J14^2+$K14^2+$L14^2), 0.5) -> 0.57543534 | I33: =I14/POWER(($H14^2+$I14^2+$J14^2+$K14^2+$L14^2), 0.5) -> 0.40280474 | J33: =J14/POWER(($H14^2+$I14^2+$J14^2+$K14^2+$L14^2), 0.5) -> 0.46034827 | K33: =K14/POWER(($H14^2+$I14^2+$J14^2+$K14^2+$L14^2), 0.5) -> 0.46034827 | L33: =L14/POWER(($H14^2+$I14^2+$J14^2+$K14^2+$L14^2), 0.5) -> 0.28771767 | O33: A1 | P33: A2 | Q33: A3 | R33: A4 | S33: A5
G34: P10 | H34: =H15/POWER(($H15^2+$I15^2+$J15^2+$K15^2+$L15^2), 0.5) -> 0.41464421 | I34: =I15/POWER(($H15^2+$I15^2+$J15^2+$K15^2+$L15^2), 0.5) -> 0.53311399 | J34: =J15/POWER(($H15^2+$I15^2+$J15^2+$K15^2+$L15^2), 0.5) -> 0.41464421 | K34: =K15/POWER(($H15^2+$I15^2+$J15^2+$K15^2+$L15^2), 0.5) -> 0.53311399 | L34: =L15/POWER(($H15^2+$I15^2+$J15^2+$K15^2+$L15^2), 0.5) -> 0.29617444 | O34: =P25/(O25+P25) -> 0.5070503 | P34: =P26/(O26+P26) -> 0.50593182 | Q34: =P27/(O27+P27) -> 0.5049294 | R34: =P28/(O28+P28) -> 0.50680226 | S34: =P29/(O29+P29) -> 0.50837962
G35: P11 | H35: =H16/POWER(($H16^2+$I16^2+$J16^2+$K16^2+$L16^2), 0.5) -> 0.35294118 | I35: =I16/POWER(($H16^2+$I16^2+$J16^2+$K16^2+$L16^2), 0.5) -> 0.47058824 | J35: =J16/POWER(($H16^2+$I16^2+$J16^2+$K16^2+$L16^2), 0.5) -> 0.29411765 | K35: =K16/POWER(($H16^2+$I16^2+$J16^2+$K16^2+$L16^2), 0.5) -> 0.47058824 | L35: =L16/POWER(($H16^2+$I16^2+$J16^2+$K16^2+$L16^2), 0.5) -> 0.58823529 | N35: Ranking | O35: =RANK(O34,O$34:S$34) -> 2 | P35: =RANK(P34,O$34:S$34) -> 4 | Q35: =RANK(Q34,O$34:S$34) -> 5 | R35: =RANK(R34,O$34:S$34) -> 3 | S35: =RANK(S34,O$34:S$34) -> 1
G36: P12 | H36: =H17/POWER(($H17^2+$I17^2+$J17^2+$K17^2+$L17^2), 0.5) -> 0.41015156 | I36: =I17/POWER(($H17^2+$I17^2+$J17^2+$K17^2+$L17^2), 0.5) -> 0.41015156 | J36: =J17/POWER(($H17^2+$I17^2+$J17^2+$K17^2+$L17^2), 0.5) -> 0.34179296 | K36: =K17/POWER(($H17^2+$I17^2+$J17^2+$K17^2+$L17^2), 0.5) -> 0.41015156 | L36: =L17/POWER(($H17^2+$I17^2+$J17^2+$K17^2+$L17^2), 0.5) -> 0.61522733
G37: P13 | H37: =H18/POWER(($H18^2+$I18^2+$J18^2+$K18^2+$L18^2), 0.5) -> 0.35112344 | I37: =I18/POWER(($H18^2+$I18^2+$J18^2+$K18^2+$L18^2), 0.5) -> 0.46816459 | J37: =J18/POWER(($H18^2+$I18^2+$J18^2+$K18^2+$L18^2), 0.5) -> 0.46816459 | K37: =K18/POWER(($H18^2+$I18^2+$J18^2+$K18^2+$L18^2), 0.5) -> 0.46816459 | L37: =L18/POWER(($H18^2+$I18^2+$J18^2+$K18^2+$L18^2), 0.5) -> 0.46816459
G38: P14 | H38: =H19/POWER(($H19^2+$I19^2+$J19^2+$K19^2+$L19^2), 0.5) -> 0.50390326 | I38: =I19/POWER(($H19^2+$I19^2+$J19^2+$K19^2+$L19^2), 0.5) -> 0.39192476 | J38: =J19/POWER(($H19^2+$I19^2+$J19^2+$K19^2+$L19^2), 0.5) -> 0.55989251 | K38: =K19/POWER(($H19^2+$I19^2+$J19^2+$K19^2+$L19^2), 0.5) -> 0.27994626 | L38: =L19/POWER(($H19^2+$I19^2+$J19^2+$K19^2+$L19^2), 0.5) -> 0.44791401
G42: 3. Matriks Keputusan dengan Nilai Numerik
H43: A1 | I43: A2 | J43: A3 | K43: A4 | L43: A5
G44: P1 | H44: =H25*$D6 -> 0 | I44: =I25*$D6 -> 0.024053512 | J44: =J25*$D6 -> 0.016035675 | K44: =K25*$D6 -> 0 | L44: =L25*$D6 -> 0.0080178373
G45: P2 | H45: =H26*$D7 -> 0.023094011 | I45: =I26*$D7 -> 0 | J45: =J26*$D7 -> 0.023094011 | K45: =K26*$D7 -> 0.023094011 | L45: =L26*$D7 -> 0
G46: P3 | H46: =H27*$D8 -> 0.061446602 | I46: =I27*$D8 -> 0.061446602 | J46: =J27*$D8 -> 0.061446602 | K46: =K27*$D8 -> 0.079002774 | L46: =L27*$D8 -> 0.070224688
G47: P4 | H47: =H28*$D9 -> 0.050093851 | I47: =I28*$D9 -> 0.071562645 | J47: =J28*$D9 -> 0.06440638 | K47: =K28*$D9 -> 0.042937587 | L47: =L28*$D9 -> 0.057250116
G48: P5 | H48: =H29*$D10 -> 0.056354707 | I48: =I29*$D10 -> 0.056354707 | J48: =J29*$D10 -> 0.033812824 | K48: =K29*$D10 -> 0.045083766 | L48: =L29*$D10 -> 0.050719236
G49: P6 | H49: =H30*$D11 -> 0.025724788 | I49: =I30*$D11 -> 0.04115966 | J49: =J30*$D11 -> 0.030869745 | K49: =K30*$D11 -> 0.051449576 | L49: =L30*$D11 -> 0.046304618
...

Sheet BORDA
B3: 1. Bobot Borda | E3: 2. Perhitungan Akhir
B4: Ranking | C4: Bobot Borda | E4: Alternatif | F4: Ranking | K4: Poin Borda | L4: Nilai Borda
B5: 1 | C5: 5 | F5: 1 | G5: 2 | H5: 3 | I5: 4 | J5: 5
B6: 2 | C6: 4 | E6: A1 | F6: ='DM1'!O34 -> 0.50844905 | G6: ='DM2'!O34 + 'DM3'!O34 -> 1.0134752 | H6: 0 | I6: 0 | J6: 0 | K6: =F6*C5+G6*C6 -> 6.5961461 | L6: =K6/K$11 -> 0.30281536 | M6: =RANK(L6,L$6:L$10) -> 1
B7: 3 | C7: 3 | E7: A2 | I7: ='DM2'!P34 + 'DM3'!P34 -> 1.0081199 | J7: ='DM1'!P34 -> 0.50326274 | K7: =I7*C8+J7*C9 -> 2.5195026 | L7: =K7/K$11 -> 0.11566513 | M7: =RANK(L7,L$6:L$10) -> 5
B8: 4 | C8: 2 | E8: A3 | H8: ='DM1'!Q34 + 'DM2'!Q34 -> 1.0104533 | J8: ='DM3'!Q34 -> 0.5049294 | K8: =H8*C7+J8*C9 -> 3.5362894 | L8: =K8/K$11 -> 0.1623437 | M8: =RANK(L8,L$6:L$10) -> 3
B9: 5 | C9: 1 | E9: A4 | F9: ='DM2'!R34 -> 0.50671097 | G9: ='DM1'!R34 -> 0.50774687 | H9: ='DM3'!R34 -> 0.50680226 | K9: =F9*C5+G9*C6+H9*C7 -> 6.0849491 | L9: =K9/K$11 -> 0.27934737 | M9: =RANK(L9,L$6:L$10) -> 2
E10: A5 | F10: ='DM3'!S34 -> 0.50837962 | I10: ='DM1'!S34 -> 0.50394764 | J10: ='DM2'!S34 -> 0.50204955 | K10: =F10*C5+I10*C9 -> 3.0458457 | L10: =K10/K$11 -> 0.13982845 | M10: =RANK(L10,L$6:L$10) -> 4
J11: total | K11: =SUM(K6:K10) -> 21.782733
